<?xml version="1.0"?>
<robot name="a2r_drone">


  <!-- <properties arm="0.185" kf="8.47e-9" km="2.13e-11" thrust2weight="4.17" max_speed_kmh="200" gnd_eff_coeff="11.36859" prop_radius="6.7e-2" drag_coeff_xy="9.1785e-7" drag_coeff_z="10.311e-7" dw_coeff_1="2267.18" dw_coeff_2=".16" dw_coeff_3="-.11" /> -->
  
  <link name="body">
    <inertial>
      <origin xyz="0 0 0" rpy="0 0 0"/>
      <mass value="0.870"/>
      <inertia ixx="0.008951" ixy="0.0" ixz="0.0" iyy="0.003102" iyz="0.0" izz="0.01161"/>
    </inertial>
    <visual>
      <origin xyz="0 0 0" rpy="0 0 0"/>
      <geometry>
        <mesh filename="../meshes/Drone.obj" scale="1 1 1"/>
      </geometry>
      <material name="drone_material">
        <color rgba="0.0 0.0 1.0 1"/>
      </material>
    </visual>
    <collision>
      <origin xyz="0 0 0" rpy="0 0 0"/>
      <geometry>
        <mesh filename="../meshes/Drone.obj" scale="1 1 1"/>
      </geometry>
    </collision>
  </link>


  <link name="prop1">
    <visual>
      <!-- <origin xyz="-0.122 -0.1343 0.013" rpy="0 0 0"/> -->
      <geometry>
        <mesh filename="../meshes/propeller.obj" scale="1 1 1"/>
      </geometry>
      <material name="propeller_material">
        <color rgba="0.0 1 0.0 1"/>
      </material>
    </visual>
    <!-- <collision>
      <origin xyz="-0.122 -0.1343 0.013" rpy="0 0 0"/>
      <geometry>
        <mesh filename="../meshes/propeller.obj" scale="1 1 1"/>
      </geometry>
    </collision> -->
  </link>
  
  
  <link name="prop2">
    <visual>
      <!-- <origin xyz="0.1482504096571687 -0.1047432515919767 0.013" rpy="0 0 0"/> -->
      <geometry>
        <mesh filename="../meshes/propeller.obj" scale="1 1 1"/>
      </geometry>
      <material name="propeller_material">
        <color rgba="0.0 1 0.0 1"/>
      </material>
    </visual>
  </link>
  

  <link name="prop3">
    <visual>
      <!-- <origin xyz="-0.122 0.1343 0.013" rpy="0 0 0"/> -->
      <geometry>
        <mesh filename="../meshes/propeller.obj" scale="1 1 1"/>
      </geometry>
      <material name="propeller_material">
        <color rgba="0.0 1 0.0 1"/>
      </material>
    </visual>
  </link>


  <link name="prop4">
    <visual>
      <!-- <origin xyz="0.1482504096571687 0.1047432515919767 0.013" rpy="0 0 0"/> -->
      <geometry>
        <mesh filename="../meshes/propeller.obj" scale="1 1 1"/>
      </geometry>
      <material name="propeller_material">
        <color rgba="0.0 1 0.0 1"/>
      </material>
    </visual>
  </link>

  <joint name="m1_joint" type="revolute">
    <parent link="body"/>
    <child link="prop1"/>
    <origin xyz="-0.122 -0.1343 0.013" rpy="0 0 0"/>
    <axis xyz="0 0 1"/>
    <dynamics damping="0.0" friction="0.0"/>
  </joint> <!--ccw-->


  <joint name="m2_joint" type="revolute">
    <parent link="body"/>
    <child link="prop2"/>
    <origin xyz="0.1482504096571687 -0.1047432515919767 0.013" rpy="0 0 0"/>
    <axis xyz="0 0 1"/>
    <dynamics damping="0.0" friction="0.0"/>
  </joint> <!--cw-->

  <joint name="m3_joint" type="revolute">
    <parent link="body"/>
    <child link="prop3"/>
    <origin xyz="-0.122 0.1343 0.013" rpy="0 0 0"/>
    <axis xyz="0 0 1"/>
    <dynamics damping="0.0" friction="0.0"/>
  </joint> <!--cw-->

  <joint name="m4_joint" type="revolute">
    <parent link="body"/>
    <child link="prop4"/>
    <origin xyz="0.1482504096571687 0.1047432515919767 0.013" rpy="0 0 0"/>
    <axis xyz="0 0 1"/>
    <dynamics damping="0.0" friction="0.0"/>
  </joint> <!--ccw-->





</robot>